Traceback (most recent call last):
  File "snippet.py", line 8, in <module>
    database='xx')
  File "/usr/local/lib/python2.7/site-packages/mysql/connector/__init__.py", line 179, in connect
    return MySQLConnection(*args, **kwargs)
  File "/usr/local/lib/python2.7/site-packages/mysql/connector/connection.py", line 95, in __init__
    self.connect(**kwargs)
  File "/usr/local/lib/python2.7/site-packages/mysql/connector/abstracts.py", line 716, in connect
    self._open_connection()
  File "/usr/local/lib/python2.7/site-packages/mysql/connector/connection.py", line 206, in _open_connection
    self._socket.open_connection()
  File "/usr/local/lib/python2.7/site-packages/mysql/connector/network.py", line 501, in open_connection
    errno=2003, values=(self.get_address(), _strioerror(err)))
mysql.connector.errors.InterfaceError: 2003: Can't connect to MySQL server on 'xx:3306' (-2 Name or service not known)
